<?xml version="1.0"?>
<robot name="robby_track2">
  <link name="base_link">
    <visual>
      <geometry>
        <box size="0.2 0.105 0.075"/>
      </geometry>
      <origin rpy="0 0 0" xyz="0.0 0.0 0.0375"/>
    </visual>
  </link>

  <link name="servo1_base">
    <visual>
      <geometry>
        <box size="0.02 0.01 0.03"/>
      </geometry>
      <origin rpy="0 0 0" xyz="0.09 0.0 0.09"/>
      <material name="blue">
        <color rgba="0 0 .8 1"/>
      </material>
    </visual>
  </link>

  <joint name="base_to_servo1" type="fixed">
    <parent link="base_link"/>
    <child link="servo1_base"/>
    <origin rpy="0 0 0" xyz="0 0 0"/>
  </joint>

  <link name="servo1_head">
    <visual>
      <geometry>
        <box size="0.03 0.05 0.03"/>
      </geometry>
      <origin rpy="0 0 0" xyz="0.0 0 0.015"/>
      <material name="grey">
        <color rgba="0.3 0.3 0.3 1"/>
      </material>
    </visual>
  </link>

  <joint name="base_to_head1" type="continuous">
    <parent link="base_link"/>
    <child link="servo1_head"/>
    <origin rpy="0 0 0" xyz="0.095 0 0.105"/>
    <axis xyz="0 0 1"/>
  </joint>

  <link name="servo2_head">
    <visual>
      <geometry>
        <box size="0.03 0.05 0.03"/>
      </geometry>
      <origin rpy="0 0 0" xyz="0.015 0.0 0.0"/>
      <material name="dark green">
        <color rgba="0.0 0.3 0.3 1"/>
      </material>
    </visual>
  </link>

  <joint name="servo1_to_servo2" type="continuous">
    <parent link="servo1_head"/>
    <child link="servo2_head"/>
    <origin rpy="0 0 0" xyz="0.0 0.0 0.03"/>
    <axis xyz="0 1 0"/>
  </joint>

  <link name="ultraSonic">
    <visual>
      <geometry>
        <box size="0.02 0.05 0.02"/>
      </geometry>
      <origin rpy="0 0 0" xyz="-0.01 0.0 0.00"/>
      <material name="white">
        <color rgba="1 1 1 1"/>
      </material>
    </visual>
  </link>

  <joint name="servo1_to_ultraSonic" type="fixed">
    <parent link="servo1_head"/>
    <child link="ultraSonic"/>
    <origin rpy="0 0 0" xyz="0.035 0.0 -0.01"/>
    <axis xyz="0 1 0"/>
  </joint>

<link name="camera_link">
  <visual>
    <geometry>
      <box size="0.010 0.130 0.019"/>
    </geometry>
    <origin rpy="0 0 0" xyz="0.0 0.0 0.0"/>
    <material name="dark blue">
      <color rgba="0.0 0.0 0.3 1"/>
    </material>
  </visual>
</link>

<joint name="servo2_to_camera_link" type="fixed">
  <parent link="servo2_head"/>
  <child link="camera_link"/>
  <origin rpy="0 0 0" xyz="0.035 -0.045 0.0"/>
  <axis xyz="0 1 0"/>
</joint>




  <link name="imu_base">
    <visual>
      <geometry>
        <box size="0.067 0.052 0.023"/>
      </geometry>
      <origin rpy="0 0 0" xyz="0.0235 0.0145 0.0865"/>
      <material name="blue">
        <color rgba="0 0 .8 1"/>
      </material>
    </visual>
  </link>

  <joint name="base_to_imu_base" type="fixed">
    <parent link="base_link"/>
    <child link="imu_base"/>
    <origin rpy="0 0 0" xyz="0 0 0"/>
  </joint>

  <link name="imu">
    <visual>
      <geometry>
        <box size="0.003 0.005 0.001"/>
      </geometry>
      <origin rpy="0 0 0" xyz="0 0 0"/>
      <material name="white">
        <color rgba="1 1 1 1"/>
      </material>
    </visual>
  </link>

  <joint name="base_to_imu" type="fixed">
    <parent link="base_link"/>
    <child link="imu"/>
    <origin rpy="0 0 -1.5707963268" xyz="0.0335 0 0.0985"/>
  </joint>

</robot>
